<sdf version='1.7'>
  <model name='monoped'>
    <link name='base'>
      <inertial>
        <pose>0 0 0 0 -0 0</pose>
        <mass>0.4672</mass>
        <inertia>
          <ixx>0.00506133</ixx>
          <ixy>0</ixy>
          <ixz>0</ixz>
          <iyy>0.00506133</iyy>
          <iyz>0</iyz>
          <izz>0.00293333</izz>
        </inertia>
      </inertial>
      <collision name='base_collision'>
        <pose>0 0 0 0 -0 0</pose>
        <geometry>
          <box>
            <size>0.2 0.2 0.3</size>
          </box>
        </geometry>
        <surface>
          <contact>
            <ode>
              <kp>1000</kp>
              <kd>1000</kd>
            </ode>
          </contact>
          <friction>
            <ode>
              <mu>0.5</mu>
              <mu2>0.5</mu2>
            </ode>
          </friction>
        </surface>
      </collision>
      <visual name='base_visual'>
        <pose>0 0 0 0 -0 0</pose>
        <geometry>
          <box>
            <size>0.2 0.2 0.3</size>
          </box>
        </geometry>
        <material>
          <script>
            <name>Gazebo/Red</name>
            <uri>file://media/materials/scripts/gazebo.material</uri>
          </script>
        </material>
      </visual>
    </link>
    <joint name='haa_joint' type='revolute'>
      <pose relative_to='base'>0 0 -0.15 2.03444 1.5708 -1.10715</pose>
      <parent>base</parent>
      <child>hipassembly</child>
      <axis>
        <xyz>0 0 1</xyz>
        <limit>
          <lower>-1.6</lower>
          <upper>1.6</upper>
          <effort>2000</effort>
          <velocity>20</velocity>
        </limit>
        <dynamics>
          <spring_reference>0</spring_reference>
          <spring_stiffness>0</spring_stiffness>
        </dynamics>
      </axis>
    </joint>
    <link name='hipassembly'>
      <pose relative_to='haa_joint'>0 0 0 0 -0 0</pose>
      <inertial>
        <pose>0 0 0 0 -0 0</pose>
        <mass>0.1168</mass>
        <inertia>
          <ixx>0.00140907</ixx>
          <ixy>0</ixy>
          <ixz>0</ixz>
          <iyy>0.0015296</iyy>
          <iyz>0</iyz>
          <izz>0.000218659</izz>
        </inertia>
      </inertial>
      <collision name='hipassembly_collision'>
        <pose>0 0 0 0 -0 0</pose>
        <geometry>
          <mesh>
            <scale>1 1 1</scale>
            <uri>model://my_legged_robots_description/meshes/leg/hipassembly.dae</uri>
          </mesh>
        </geometry>
        <surface>
          <contact>
            <ode>
              <kp>1000</kp>
              <kd>1000</kd>
            </ode>
          </contact>
          <friction>
            <ode>
              <mu>0.5</mu>
              <mu2>0.5</mu2>
            </ode>
          </friction>
        </surface>
      </collision>
      <visual name='hipassembly_visual'>
        <pose>0 0 0 0 -0 0</pose>
        <geometry>
          <mesh>
            <scale>1 1 1</scale>
            <uri>model://my_legged_robots_description/meshes/leg/hipassembly.dae</uri>
          </mesh>
        </geometry>
      </visual>
    </link>
    <joint name='hfe_joint' type='revolute'>
      <pose relative_to='hipassembly'>0.08 0 0 1.5708 -0 0</pose>
      <parent>hipassembly</parent>
      <child>upperleg</child>
      <axis>
        <xyz>0 0 1</xyz>
        <limit>
          <lower>-1.6</lower>
          <upper>1.6</upper>
          <effort>2000</effort>
          <velocity>20</velocity>
        </limit>
        <dynamics>
          <spring_reference>0</spring_reference>
          <spring_stiffness>0</spring_stiffness>
        </dynamics>
      </axis>
    </joint>
    <link name='upperleg'>
      <pose relative_to='hfe_joint'>0 0 0 0 -0 0</pose>
      <inertial>
        <pose>0 0 0 0 -0 0</pose>
        <mass>0.1168</mass>
        <inertia>
          <ixx>0.000119503</ixx>
          <ixy>0</ixy>
          <ixz>0</ixz>
          <iyy>0.00158479</iyy>
          <iyz>0</iyz>
          <izz>0.00158586</izz>
        </inertia>
      </inertial>
      <collision name='upperleg_collision'>
        <pose>0 0 0 0 -0 0</pose>
        <geometry>
          <mesh>
            <scale>1 1 1</scale>
            <uri>model://my_legged_robots_description/meshes/leg/upperleg.dae</uri>
          </mesh>
        </geometry>
        <surface>
          <contact>
            <ode>
              <kp>1000</kp>
              <kd>1000</kd>
            </ode>
          </contact>
          <friction>
            <ode>
              <mu>0.5</mu>
              <mu2>0.5</mu2>
            </ode>
          </friction>
        </surface>
      </collision>
      <visual name='upperleg_visual'>
        <pose>0 0 0 0 -0 0</pose>
        <geometry>
          <mesh>
            <scale>1 1 1</scale>
            <uri>model://my_legged_robots_description/meshes/leg/upperleg.dae</uri>
          </mesh>
        </geometry>
      </visual>
    </link>
    <joint name='kfe_joint' type='revolute'>
      <pose relative_to='upperleg'>0.35 0 0 0 -0 0</pose>
      <parent>upperleg</parent>
      <child>lowerleg</child>
      <axis>
        <xyz>0 0 1</xyz>
        <limit>
          <lower>-1.6</lower>
          <upper>0</upper>
          <effort>2000</effort>
          <velocity>20</velocity>
        </limit>
        <dynamics>
          <spring_reference>0</spring_reference>
          <spring_stiffness>0</spring_stiffness>
        </dynamics>
      </axis>
    </joint>
    <link name='lowerleg'>
      <pose relative_to='kfe_joint'>0 0 0 0 -0 0</pose>
      <inertial>
        <pose>0.001195 0 0 0 -0 0</pose>
        <mass>0.0293</mass>
        <inertia>
          <ixx>1.74314e-05</ixx>
          <ixy>0</ixy>
          <ixz>0</ixz>
          <iyy>0.000383113</iyy>
          <iyz>0</iyz>
          <izz>0.000375996</izz>
        </inertia>
      </inertial>
      <collision name='lowerleg_collision'>
        <pose>0 0 0 0 -0 0</pose>
        <geometry>
          <mesh>
            <scale>1 1 1</scale>
            <uri>model://my_legged_robots_description/meshes/leg/lowerleg.dae</uri>
          </mesh>
        </geometry>
        <surface>
          <contact>
            <ode>
              <kp>1000</kp>
              <kd>1000</kd>
            </ode>
          </contact>
          <friction>
            <ode>
              <mu>0.5</mu>
              <mu2>0.5</mu2>
            </ode>
          </friction>
        </surface>
      </collision>
      <collision name='lowerleg_contactsensor_link_collision_1'>
        <pose>0.35 0 0 0 -0 0</pose>
        <geometry>
          <sphere>
            <radius>0.02</radius>
          </sphere>
        </geometry>
        <surface>
          <contact>
            <ode>
              <kp>1000</kp>
              <kd>1000</kd>
            </ode>
          </contact>
          <friction>
            <ode>
              <mu>0.5</mu>
              <mu2>0.5</mu2>
            </ode>
          </friction>
        </surface>
      </collision>
      <visual name='lowerleg_visual'>
        <pose>0 0 0 0 -0 0</pose>
        <geometry>
          <mesh>
            <scale>1 1 1</scale>
            <uri>model://my_legged_robots_description/meshes/leg/lowerleg.dae</uri>
          </mesh>
        </geometry>
      </visual>
      <visual name='lowerleg_contactsensor_link_visual_1'>
        <pose>0.35 0 0 0 -0 0</pose>
        <geometry>
          <sphere>
            <radius>0.02</radius>
          </sphere>
        </geometry>
      </visual>
      <sensor name='lowerleg_contactsensor_sensor' type='contact'>
        <always_on>1</always_on>
        <contact>
          <collision>lowerleg_contactsensor_link_collision_1</collision>
          <topic>__default_topic__</topic>
        </contact>
        <plugin name='bumper0_plugin' filename='libgazebo_ros_bumper.so'>
          <bumperTopicName>lowerleg_contactsensor_state</bumperTopicName>
          <frameName>lowerleg_contactsensor_link</frameName>
        </plugin>
        <pose>0.35 0 0 0 -0 0</pose>
      </sensor>
    </link>
    <plugin name='gazebo_ros_control' filename='libgazebo_ros_control.so'>
      <robotNamespace>/monoped</robotNamespace>
    </plugin>
    <plugin name='p3d_base_controller' filename='libgazebo_ros_p3d.so'>
      <alwaysOn>1</alwaysOn>
      <bodyName>base</bodyName>
      <topicName>odom</topicName>
      <gaussianNoise>0.01</gaussianNoise>
      <frameName>world</frameName>
      <xyzOffsets>0 0 0</xyzOffsets>
      <rpyOffsets>0 0 0</rpyOffsets>
    </plugin>
    <static>0</static>
    <plugin name='gazebo_ros_imu_controller' filename='libgazebo_ros_imu.so'>
      <robotNamespace>/monoped</robotNamespace>
      <topicName>imu/data</topicName>
      <serviceName>imu/service</serviceName>
      <bodyName>base</bodyName>
      <gaussianNoise>0</gaussianNoise>
      <rpyOffsets>0 0 0</rpyOffsets>
      <alwaysOn>1</alwaysOn>
      <gaussianNoise>0</gaussianNoise>
    </plugin>
  </model>
</sdf>
